[2024-03-24 08:40:13,872] {taskinstance.py:896} INFO - Dependencies all met for <TaskInstance: weather_data_pipeline.train_random_forest 2024-03-24T08:36:00+00:00 [queued]>
[2024-03-24 08:40:13,901] {taskinstance.py:896} INFO - Dependencies all met for <TaskInstance: weather_data_pipeline.train_random_forest 2024-03-24T08:36:00+00:00 [queued]>
[2024-03-24 08:40:13,908] {taskinstance.py:1087} INFO - 
--------------------------------------------------------------------------------
[2024-03-24 08:40:13,910] {taskinstance.py:1088} INFO - Starting attempt 2 of 2
[2024-03-24 08:40:13,910] {taskinstance.py:1089} INFO - 
--------------------------------------------------------------------------------
[2024-03-24 08:40:13,938] {taskinstance.py:1107} INFO - Executing <Task(PythonOperator): train_random_forest> on 2024-03-24T08:36:00+00:00
[2024-03-24 08:40:13,960] {standard_task_runner.py:52} INFO - Started process 16850 to run task
[2024-03-24 08:40:13,974] {standard_task_runner.py:76} INFO - Running: ['***', 'tasks', 'run', 'weather_data_pipeline', 'train_random_forest', '2024-03-24T08:36:00+00:00', '--job-id', '762', '--pool', 'default_pool', '--raw', '--subdir', 'DAGS_FOLDER/file.py', '--cfg-path', '/tmp/tmp1vua5ltr', '--error-file', '/tmp/tmpqx1swnez']
[2024-03-24 08:40:13,975] {standard_task_runner.py:77} INFO - Job 762: Subtask train_random_forest
[2024-03-24 08:40:14,129] {logging_mixin.py:104} INFO - Running <TaskInstance: weather_data_pipeline.train_random_forest 2024-03-24T08:36:00+00:00 [running]> on host ce3400b6b8c4
[2024-03-24 08:40:14,426] {taskinstance.py:1302} INFO - Exporting the following env vars:
AIRFLOW_CTX_DAG_OWNER=***
AIRFLOW_CTX_DAG_ID=weather_data_pipeline
AIRFLOW_CTX_TASK_ID=train_random_forest
AIRFLOW_CTX_EXECUTION_DATE=2024-03-24T08:36:00+00:00
AIRFLOW_CTX_DAG_RUN_ID=scheduled__2024-03-24T08:36:00+00:00
[2024-03-24 08:40:14,781] {logging_mixin.py:104} WARNING - /home/***/.local/lib/python3.6/site-packages/pandas/core/indexing.py:1596 SettingWithCopyWarning:
A value is trying to be set on a copy of a slice from a DataFrame.
Try using .loc[row_indexer,col_indexer] = value instead

See the caveats in the documentation: https://pandas.pydata.org/pandas-docs/stable/user_guide/indexing.html#returning-a-view-versus-a-copy
[2024-03-24 08:40:14,804] {logging_mixin.py:104} WARNING - /home/***/.local/lib/python3.6/site-packages/pandas/core/indexing.py:1743 SettingWithCopyWarning:
A value is trying to be set on a copy of a slice from a DataFrame.
Try using .loc[row_indexer,col_indexer] = value instead

See the caveats in the documentation: https://pandas.pydata.org/pandas-docs/stable/user_guide/indexing.html#returning-a-view-versus-a-copy
[2024-03-24 08:40:15,070] {logging_mixin.py:104} WARNING - /home/***/.local/lib/python3.6/site-packages/pandas/core/indexing.py:1596 SettingWithCopyWarning:
A value is trying to be set on a copy of a slice from a DataFrame.
Try using .loc[row_indexer,col_indexer] = value instead

See the caveats in the documentation: https://pandas.pydata.org/pandas-docs/stable/user_guide/indexing.html#returning-a-view-versus-a-copy
[2024-03-24 08:40:15,079] {logging_mixin.py:104} WARNING - /home/***/.local/lib/python3.6/site-packages/pandas/core/indexing.py:1743 SettingWithCopyWarning:
A value is trying to be set on a copy of a slice from a DataFrame.
Try using .loc[row_indexer,col_indexer] = value instead

See the caveats in the documentation: https://pandas.pydata.org/pandas-docs/stable/user_guide/indexing.html#returning-a-view-versus-a-copy
[2024-03-24 08:40:15,210] {logging_mixin.py:104} WARNING - /home/***/.local/lib/python3.6/site-packages/pandas/core/indexing.py:1596 SettingWithCopyWarning:
A value is trying to be set on a copy of a slice from a DataFrame.
Try using .loc[row_indexer,col_indexer] = value instead

See the caveats in the documentation: https://pandas.pydata.org/pandas-docs/stable/user_guide/indexing.html#returning-a-view-versus-a-copy
[2024-03-24 08:40:15,217] {logging_mixin.py:104} WARNING - /home/***/.local/lib/python3.6/site-packages/pandas/core/indexing.py:1743 SettingWithCopyWarning:
A value is trying to be set on a copy of a slice from a DataFrame.
Try using .loc[row_indexer,col_indexer] = value instead

See the caveats in the documentation: https://pandas.pydata.org/pandas-docs/stable/user_guide/indexing.html#returning-a-view-versus-a-copy
[2024-03-24 08:40:15,306] {logging_mixin.py:104} WARNING - /home/***/.local/lib/python3.6/site-packages/pandas/core/indexing.py:1596 SettingWithCopyWarning:
A value is trying to be set on a copy of a slice from a DataFrame.
Try using .loc[row_indexer,col_indexer] = value instead

See the caveats in the documentation: https://pandas.pydata.org/pandas-docs/stable/user_guide/indexing.html#returning-a-view-versus-a-copy
[2024-03-24 08:40:15,324] {logging_mixin.py:104} WARNING - /home/***/.local/lib/python3.6/site-packages/pandas/core/indexing.py:1743 SettingWithCopyWarning:
A value is trying to be set on a copy of a slice from a DataFrame.
Try using .loc[row_indexer,col_indexer] = value instead

See the caveats in the documentation: https://pandas.pydata.org/pandas-docs/stable/user_guide/indexing.html#returning-a-view-versus-a-copy
[2024-03-24 08:40:15,388] {logging_mixin.py:104} WARNING - /home/***/.local/lib/python3.6/site-packages/pandas/core/indexing.py:1596 SettingWithCopyWarning:
A value is trying to be set on a copy of a slice from a DataFrame.
Try using .loc[row_indexer,col_indexer] = value instead

See the caveats in the documentation: https://pandas.pydata.org/pandas-docs/stable/user_guide/indexing.html#returning-a-view-versus-a-copy
[2024-03-24 08:40:15,395] {logging_mixin.py:104} WARNING - /home/***/.local/lib/python3.6/site-packages/pandas/core/indexing.py:1743 SettingWithCopyWarning:
A value is trying to be set on a copy of a slice from a DataFrame.
Try using .loc[row_indexer,col_indexer] = value instead

See the caveats in the documentation: https://pandas.pydata.org/pandas-docs/stable/user_guide/indexing.html#returning-a-view-versus-a-copy
[2024-03-24 08:40:15,487] {logging_mixin.py:104} WARNING - /home/***/.local/lib/python3.6/site-packages/pandas/core/indexing.py:1596 SettingWithCopyWarning:
A value is trying to be set on a copy of a slice from a DataFrame.
Try using .loc[row_indexer,col_indexer] = value instead

See the caveats in the documentation: https://pandas.pydata.org/pandas-docs/stable/user_guide/indexing.html#returning-a-view-versus-a-copy
[2024-03-24 08:40:15,492] {logging_mixin.py:104} WARNING - /home/***/.local/lib/python3.6/site-packages/pandas/core/indexing.py:1743 SettingWithCopyWarning:
A value is trying to be set on a copy of a slice from a DataFrame.
Try using .loc[row_indexer,col_indexer] = value instead

See the caveats in the documentation: https://pandas.pydata.org/pandas-docs/stable/user_guide/indexing.html#returning-a-view-versus-a-copy
[2024-03-24 08:40:15,938] {logging_mixin.py:104} WARNING - /home/***/.local/lib/python3.6/site-packages/pandas/core/indexing.py:1596 SettingWithCopyWarning:
A value is trying to be set on a copy of a slice from a DataFrame.
Try using .loc[row_indexer,col_indexer] = value instead

See the caveats in the documentation: https://pandas.pydata.org/pandas-docs/stable/user_guide/indexing.html#returning-a-view-versus-a-copy
[2024-03-24 08:40:16,019] {logging_mixin.py:104} WARNING - /home/***/.local/lib/python3.6/site-packages/pandas/core/indexing.py:1743 SettingWithCopyWarning:
A value is trying to be set on a copy of a slice from a DataFrame.
Try using .loc[row_indexer,col_indexer] = value instead

See the caveats in the documentation: https://pandas.pydata.org/pandas-docs/stable/user_guide/indexing.html#returning-a-view-versus-a-copy
[2024-03-24 08:40:16,344] {logging_mixin.py:104} WARNING - /home/***/.local/lib/python3.6/site-packages/pandas/core/indexing.py:1596 SettingWithCopyWarning:
A value is trying to be set on a copy of a slice from a DataFrame.
Try using .loc[row_indexer,col_indexer] = value instead

See the caveats in the documentation: https://pandas.pydata.org/pandas-docs/stable/user_guide/indexing.html#returning-a-view-versus-a-copy
[2024-03-24 08:40:16,378] {logging_mixin.py:104} WARNING - /home/***/.local/lib/python3.6/site-packages/pandas/core/indexing.py:1743 SettingWithCopyWarning:
A value is trying to be set on a copy of a slice from a DataFrame.
Try using .loc[row_indexer,col_indexer] = value instead

See the caveats in the documentation: https://pandas.pydata.org/pandas-docs/stable/user_guide/indexing.html#returning-a-view-versus-a-copy
[2024-03-24 08:40:16,665] {logging_mixin.py:104} WARNING - /home/***/.local/lib/python3.6/site-packages/pandas/core/indexing.py:1596 SettingWithCopyWarning:
A value is trying to be set on a copy of a slice from a DataFrame.
Try using .loc[row_indexer,col_indexer] = value instead

See the caveats in the documentation: https://pandas.pydata.org/pandas-docs/stable/user_guide/indexing.html#returning-a-view-versus-a-copy
[2024-03-24 08:40:16,712] {logging_mixin.py:104} WARNING - /home/***/.local/lib/python3.6/site-packages/pandas/core/indexing.py:1743 SettingWithCopyWarning:
A value is trying to be set on a copy of a slice from a DataFrame.
Try using .loc[row_indexer,col_indexer] = value instead

See the caveats in the documentation: https://pandas.pydata.org/pandas-docs/stable/user_guide/indexing.html#returning-a-view-versus-a-copy
[2024-03-24 08:40:17,192] {taskinstance.py:1501} ERROR - Task failed with exception
Traceback (most recent call last):
  File "/home/airflow/.local/lib/python3.6/site-packages/joblib/parallel.py", line 825, in dispatch_one_batch
    tasks = self._ready_batches.get(block=False)
  File "/usr/local/lib/python3.6/queue.py", line 161, in get
    raise Empty
queue.Empty

During handling of the above exception, another exception occurred:

Traceback (most recent call last):
  File "/home/airflow/.local/lib/python3.6/site-packages/airflow/models/taskinstance.py", line 1157, in _run_raw_task
    self._prepare_and_execute_task_with_callbacks(context, task)
  File "/home/airflow/.local/lib/python3.6/site-packages/airflow/models/taskinstance.py", line 1331, in _prepare_and_execute_task_with_callbacks
    result = self._execute_task(context, task_copy)
  File "/home/airflow/.local/lib/python3.6/site-packages/airflow/models/taskinstance.py", line 1361, in _execute_task
    result = task_copy.execute(context=context)
  File "/home/airflow/.local/lib/python3.6/site-packages/airflow/operators/python.py", line 150, in execute
    return_value = self.execute_callable()
  File "/home/airflow/.local/lib/python3.6/site-packages/airflow/operators/python.py", line 161, in execute_callable
    return self.python_callable(*self.op_args, **self.op_kwargs)
  File "/opt/airflow/dags/file.py", line 119, in compute_model_score
    score = cross_val_score(model, X, y, cv=3, scoring='neg_mean_squared_error').mean()
  File "/home/airflow/.local/lib/python3.6/site-packages/sklearn/utils/validation.py", line 63, in inner_f
    return f(*args, **kwargs)
  File "/home/airflow/.local/lib/python3.6/site-packages/sklearn/model_selection/_validation.py", line 450, in cross_val_score
    error_score=error_score)
  File "/home/airflow/.local/lib/python3.6/site-packages/sklearn/utils/validation.py", line 63, in inner_f
    return f(*args, **kwargs)
  File "/home/airflow/.local/lib/python3.6/site-packages/sklearn/model_selection/_validation.py", line 256, in cross_validate
    for train, test in cv.split(X, y, groups))
  File "/home/airflow/.local/lib/python3.6/site-packages/joblib/parallel.py", line 1048, in __call__
    if self.dispatch_one_batch(iterator):
  File "/home/airflow/.local/lib/python3.6/site-packages/joblib/parallel.py", line 836, in dispatch_one_batch
    islice = list(itertools.islice(iterator, big_batch_size))
  File "/home/airflow/.local/lib/python3.6/site-packages/sklearn/model_selection/_validation.py", line 251, in <genexpr>
    delayed(_fit_and_score)(
  File "/home/airflow/.local/lib/python3.6/site-packages/sklearn/model_selection/_split.py", line 330, in split
    .format(self.n_splits, n_samples))
ValueError: Cannot have number of splits n_splits=3 greater than the number of samples: n_samples=0.
[2024-03-24 08:40:17,321] {taskinstance.py:1551} INFO - Marking task as FAILED. dag_id=weather_data_pipeline, task_id=train_random_forest, execution_date=20240324T083600, start_date=20240324T084013, end_date=20240324T084017
[2024-03-24 08:40:17,575] {local_task_job.py:151} INFO - Task exited with return code 1
